<?xml version="1" ?>
<!-- =================================================================================== -->
<!-- This document is combination of following:  -->

<!-- ur5e.urdf.xacro -->

 <!-- =================================================================================== -->
 <robot name="ur5e" xmlns:xacro="http://ros.org/wiki/xacro">
    <material name="black">
        <color rgba="0 0 0 1"/>
    </material>
    <material name="LightGrey">
        <color rgba="0.7 0.7 0.7 1.0"/>
    </material>
    <material name="darkgrey">
        <color rgba="0.3 0.3 0.3 1"/>
    </material>
    <material name="grey">
        <color rgba="0.5 0.5 0.5 1"/>
    </material>
    <material name="firebrick">
        <color rgba="0.545 0.102 0.102 1"/>
    </material>
    <material name="white">
        <color rgba="0.9 0.9 0.9 1"/>
    </material>
    <material  name="Black" >
     <color  rgba="0 0 0 1" />
    </material>
    <material  name="Blue" >
     <color  rgba="0.0 0.0 0.8 1.0" />
    </material>
    <material  name="Green" >
     <color  rgba="0.0 0.8 0.0 1.0" />
    </material>
    <material  name="Grey" >
     <color  rgba="0.4 0.4 0.4 1.0" />
    </material>
    <material  name="Orange" >
     <color  rgba="1.0 0.4235294117647059 0.0392156862745098 1.0" />
    </material>
    <material  name="Brown" >
     <color  rgba="0.8705882352941177 0.8117647058823529 0.7647058823529411 1.0" />
    </material>
    <material  name="Red" >
     <color  rgba="0.8 0.0 0.0 1.0" />
    </material>
    <material  name="BananaYellow" >
     <color  rgba="0.9803921568627451 0.996078431372549 0.29411764705882354 1.0" />
    </material>
    <material  name="BrightBlue" >
     <color  rgba="0.00392156862745098 0.396078431372549 0.9882352941176471 1.0" />
    </material>
    <material  name="White" >
     <color  rgba="1.0 1.0 1.0 1.0" />
    </material>
   <link name="base_link">
     <visual>
       <geometry>
         <mesh filename="ur5e_robot/collision/base.stl"/>
       </geometry>
       <material name="LightGrey">
         <color rgba="0.7 0.7 0.7 1.0"/>
       </material>
     </visual>
     <collision>
       <geometry>
         <mesh filename="ur5e_robot/collision/base.stl" scale="1.0 1.0 1.0"/>
       </geometry>
     </collision>
     <inertial>
       <mass value="4.0"/>
       <origin rpy="0 0 0" xyz="0.0 0.0 0.0"/>
       <inertia ixx="0.00443333156" ixy="0.0" ixz="0.0" iyy="0.00443333156" iyz="0.0" izz="0.0072"/>
     </inertial>
   </link>
   <joint name="shoulder_pan_joint" type="revolute">
     <parent link="base_link"/>
     <child link="shoulder_link"/>
     <origin rpy="0.0 0.0 0.0" xyz="0.0 0.0 0.163"/>
     <axis xyz="0 0 1"/>
     <limit effort="150.0" lower="-6.28318530718" upper="6.28318530718" velocity="1"/>
     <dynamics damping="0.0" friction="0.0"/>
   </joint>
   <link name="shoulder_link">
     <visual>
       <geometry>
         <mesh filename="ur5e_robot//collision//shoulder.stl"/>
       </geometry>
       <material name="darkgrey"/>
     </visual>
     <collision>
       <geometry>
         <mesh filename="ur5e_robot//collision//shoulder.stl" scale="1.0 1.0 1.0"/>
       </geometry>
     </collision>
     <inertial>
       <mass value="3.7"/>
       <origin rpy="0 0 0" xyz="0.0 0.0 0.0"/>
       <inertia ixx="0.010267495893" ixy="0.0" ixz="0.0" iyy="0.010267495893" iyz="0.0" izz="0.00666"/>
     </inertial>
   </link>
   <joint name="shoulder_lift_joint" type="revolute">
     <parent link="shoulder_link"/>
     <child link="upper_arm_link"/>
     <origin rpy="0.0 1.57079632679 0.0" xyz="0.0 0.138 0.0"/>
     <axis xyz="0 1 0"/>
     <limit effort="150.0" lower="-6.28318530718" upper="6.28318530718" velocity="1"/>
     <dynamics damping="0.0" friction="0.0"/>
   </joint>
   <link name="upper_arm_link">
     <visual>
       <geometry>
         <mesh filename="ur5e_robot//collision//upperarm.stl"/>
       </geometry>
       <material name="LightGrey"/>
     </visual>
     <collision>
       <geometry>
         <mesh filename="ur5e_robot//collision//upperarm.stl" scale="1.0 1.0 1.0"/>
       </geometry>
     </collision>
     <inertial>
       <mass value="8.393"/>
       <origin rpy="0 0 0" xyz="0.0 0.0 0.2125"/>
       <inertia ixx="0.133885781862" ixy="0.0" ixz="0.0" iyy="0.133885781862" iyz="0.0" izz="0.0151074"/>
     </inertial>
   </link>
   <joint name="elbow_joint" type="revolute">
     <parent link="upper_arm_link"/>
     <child link="forearm_link"/>
     <origin rpy="0.0 0.0 0.0" xyz="0.0 -0.131 0.425"/>
     <axis xyz="0 1 0"/>
     <limit effort="150.0" lower="-3.14159265359" upper="3.14159265359" velocity="1"/>
     <dynamics damping="0.0" friction="0.0"/>
   </joint>
   <link name="forearm_link">
     <visual>
       <geometry>
         <mesh filename="ur5e_robot//collision//forearm.stl"/>
       </geometry>
       <material name="LightGrey"/>

     </visual>
     <collision>
       <geometry>
         <mesh filename="ur5e_robot//collision//forearm.stl" scale="1.0 1.0 1.0"/>
       </geometry>
     </collision>
     <inertial>
       <mass value="2.275"/>
       <origin rpy="0 0 0" xyz="0.0 0.0 0.196"/>
       <inertia ixx="0.0311796208615" ixy="0.0" ixz="0.0" iyy="0.0311796208615" iyz="0.0" izz="0.004095"/>
     </inertial>
   </link>
   <joint name="wrist_1_joint" type="revolute">
     <parent link="forearm_link"/>
     <child link="wrist_1_link"/>
     <origin rpy="0.0 1.57079632679 0.0" xyz="0.0 0.0 0.392"/>
     <axis xyz="0 1 0"/>
     <limit effort="28.0" lower="-6.28318530718" upper="6.28318530718" velocity="1"/>
     <dynamics damping="0.0" friction="0.0"/>
   </joint>
   <link name="wrist_1_link">
     <visual>
       <geometry>
         <mesh filename="ur5e_robot//collision//wrist1.stl"/>
       </geometry>
       <material name="darkgrey"/>

     </visual>
     <collision>
       <geometry>
         <mesh filename="ur5e_robot//collision//wrist1.stl" scale="1.0 1.0 1.0"/>
       </geometry>
     </collision>
     <inertial>
       <mass value="1.219"/>
       <origin rpy="0 0 0" xyz="0.0 0.127 0.0"/>
       <inertia ixx="0.00255989897604" ixy="0.0" ixz="0.0" iyy="0.00255989897604" iyz="0.0" izz="0.0021942"/>
     </inertial>
   </link>
   <joint name="wrist_2_joint" type="revolute">
     <parent link="wrist_1_link"/>
     <child link="wrist_2_link"/>
     <origin rpy="0.0 0.0 0.0" xyz="0.0 0.127 0.0"/>
     <axis xyz="0 0 1"/>
     <limit effort="28.0" lower="-6.28318530718" upper="6.28318530718" velocity="1"/>
     <dynamics damping="0.0" friction="0.0"/>
   </joint>
   <link name="wrist_2_link">
     <visual>
       <geometry>
         <mesh filename="ur5e_robot//collision//wrist2.stl"/>
       </geometry>
       <material name="darkgrey"/>
     </visual>
     <collision>
       <geometry>
         <mesh filename="ur5e_robot//collision//wrist2.stl" scale="1.0 1.0 1.0"/>
       </geometry>
     </collision>
     <inertial>
       <mass value="1.219"/>
       <origin rpy="0 0 0" xyz="0.0 0.0 0.1"/>
       <inertia ixx="0.00255989897604" ixy="0.0" ixz="0.0" iyy="0.00255989897604" iyz="0.0" izz="0.0021942"/>
     </inertial>
   </link>
   <joint name="wrist_3_joint" type="revolute">
     <parent link="wrist_2_link"/>
     <child link="wrist_3_link"/>
     <origin rpy="0.0 0.0 0.0" xyz="0.0 0.0 0.1"/>
     <axis xyz="0 1 0"/>
     <limit effort="28.0" lower="-6.28318530718" upper="6.28318530718" velocity="1"/>
     <dynamics damping="0.0" friction="0.0"/>
   </joint>
   <link name="wrist_3_link">
     <visual>
       <geometry>
         <mesh filename="ur5e_robot//collision//wrist3.stl"/>
       </geometry>
       <material name="LightGrey"/>
     </visual>
     <collision>
       <geometry>
         <mesh filename="ur5e_robot//collision//wrist3.stl" scale="1.0 1.0 1.0"/>
       </geometry>
     </collision>
     <inertial>
       <mass value="0.1879"/>
       <origin rpy="1.57079632679 0 0" xyz="0.0 0.0771 0.0"/>
       <inertia ixx="9.89041005217e-05" ixy="0.0" ixz="0.0" iyy="9.89041005217e-05" iyz="0.0" izz="0.0001321171875"/>
     </inertial>
   </link>
   <joint name="ee_link" type="fixed">
     <parent link="wrist_3_link"/>
     <child link="ee_link"/>
     <origin rpy="0.0 0.0 1.57079632679" xyz="0.0 0.1 0.0"/>
   </joint>
   <link name="ee_link">
     <collision>
       <geometry>
         <box size="0.01 0.01 0.01"/>
       </geometry>
       <origin rpy="0 0 0" xyz="-0.01 0 0"/>
     </collision>
   </link>
   <transmission name="shoulder_pan_trans">
     <type>transmission_interface/SimpleTransmission</type>
     <joint name="shoulder_pan_joint">
       <hardwareInterface>hardware_interface/PositionJointInterface</hardwareInterface>
     </joint>
     <actuator name="shoulder_pan_motor">
       <mechanicalReduction>1</mechanicalReduction>
     </actuator>
   </transmission>
   <transmission name="shoulder_lift_trans">
     <type>transmission_interface/SimpleTransmission</type>
     <joint name="shoulder_lift_joint">
       <hardwareInterface>hardware_interface/PositionJointInterface</hardwareInterface>
     </joint>
     <actuator name="shoulder_lift_motor">
       <mechanicalReduction>1</mechanicalReduction>
     </actuator>
   </transmission>
   <transmission name="elbow_trans">
     <type>transmission_interface/SimpleTransmission</type>
     <joint name="elbow_joint">
       <hardwareInterface>hardware_interface/PositionJointInterface</hardwareInterface>
     </joint>
     <actuator name="elbow_motor">
       <mechanicalReduction>1</mechanicalReduction>
     </actuator>
   </transmission>
   <transmission name="wrist_1_trans">
     <type>transmission_interface/SimpleTransmission</type>
     <joint name="wrist_1_joint">
       <hardwareInterface>hardware_interface/PositionJointInterface</hardwareInterface>
     </joint>
     <actuator name="wrist_1_motor">
       <mechanicalReduction>1</mechanicalReduction>
     </actuator>
   </transmission>
   <transmission name="wrist_2_trans">
     <type>transmission_interface/SimpleTransmission</type>
     <joint name="wrist_2_joint">
       <hardwareInterface>hardware_interface/PositionJointInterface</hardwareInterface>
     </joint>
     <actuator name="wrist_2_motor">
       <mechanicalReduction>1</mechanicalReduction>
     </actuator>
   </transmission>
   <transmission name="wrist_3_trans">
     <type>transmission_interface/SimpleTransmission</type>
     <joint name="wrist_3_joint">
       <hardwareInterface>hardware_interface/PositionJointInterface</hardwareInterface>
     </joint>
     <actuator name="wrist_3_motor">
       <mechanicalReduction>1</mechanicalReduction>
     </actuator>
   </transmission>
   <gazebo reference="shoulder_link">
     <selfCollide>true</selfCollide>
   </gazebo>
   <gazebo reference="upper_arm_link">
     <selfCollide>true</selfCollide>
   </gazebo>
   <gazebo reference="forearm_link">
     <selfCollide>true</selfCollide>
   </gazebo>
   <gazebo reference="wrist_1_link">
     <selfCollide>true</selfCollide>
   </gazebo>
   <gazebo reference="wrist_3_link">
     <selfCollide>true</selfCollide>
   </gazebo>
   <gazebo reference="wrist_2_link">
     <selfCollide>true</selfCollide>
   </gazebo>
   <gazebo reference="ee_link">
     <selfCollide>true</selfCollide>
   </gazebo>
   <!-- ROS base_link to UR 'Base' Coordinates transform -->
   <link name="base"/>
   <joint name="base_link-base_fixed_joint" type="fixed">
     <!-- NOTE: this rotation is only needed as long as base_link itself is
                  not corrected wrt the real robot (ie: rotated over 180
                  degrees)
       -->
     <origin rpy="0 0 -3.14159265359" xyz="0 0 0"/>
     <parent link="base_link"/>
     <child link="base"/>
   </joint>
   <!-- Frame coincident with all-zeros TCP on UR controller -->
   <link name="tool0"/>
   <joint name="wrist_3_link-tool0_fixed_joint" type="fixed">
     <origin rpy="-1.57079632679 0 0" xyz="0 0.1 0"/>
     <parent link="wrist_3_link"/>
     <child link="tool0"/>
   </joint>
   <link name="world"/>
   <joint name="world_joint" type="fixed">
     <parent link="world"/>
     <child link="base_link"/>
     <origin rpy="0.0 0.0 0.0" xyz="0.0 0.0 0.0"/>
   </joint>

   <!-- delta.urdf -->
   <joint  type="fixed"  name="base_joint" >
    <parent  link="ee_link" />
    <child  link="dbase_link" />
    <origin  rpy="0 1.57079632679 0"  xyz="0 0.0 0" />
   </joint>
   <link  name="dbase_link" >
    <inertial >
     <mass  value="0.01" />
     <inertia  izz="0.001"  ixz="0.0"  iyy="0.001"  ixy="0.0"  iyz="0.0"  ixx="0.001" />
    </inertial>
    <visual >
     <origin  xyz="0 0 0"  rpy="0 0 0" />
     <geometry >
      <cylinder  length="0.01"  radius="0.03" />
     </geometry>
     <material  name="Grey" />
    </visual>
    <collision >
     <origin  xyz="0 0 0"  rpy="0 0 0" />
     <geometry >
      <cylinder  length="0.01"  radius="0.03" />
     </geometry>
     <material  name="Grey" />
    </collision>
   </link>
   <joint  name="motor_joint_1"  type="prismatic" >
    <axis  xyz="0 0 1" />
    <limit  velocity="1"  upper="0.1"  lower="0.0"  effort="100" />
    <parent  link="dbase_link" />
    <child  link="motor_link_1" />
    <origin  xyz="0 0 0"  rpy="0 0 0" />
   </joint>
   <link  name="motor_link_1" >
    <inertial >
     <mass  value="0.01" />
     <inertia  izz="0.001"  ixz="0.0"  iyy="0.001"  ixy="0.0"  iyz="0.0"  ixx="0.001" />
    </inertial>
    <visual >
     <origin  xyz="0 0 0.01"  rpy="0 0 0" />
     <geometry >
      <box  size="0.01 0.002 0.02" />
     </geometry>
     <material  name="BrightBlue" />
    </visual>
    <collision >
     <origin  xyz="0 0 0.01"  rpy="0 0 0" />
     <geometry >
      <box  size="0.01 0.002 0.02" />
     </geometry>
     <material  name="BrightBlue" />
    </collision>
   </link>
   <joint  name="motor_joint_2"  type="prismatic" >
    <axis  xyz="0 0 1" />
    <limit  velocity="1"  upper="0.1"  lower="0.0"  effort="100" />
    <parent  link="dbase_link" />
    <child  link="motor_link_2" />
    <origin  xyz="0.017320508075688773 -0.06 0.0"  rpy="0 0 -2.0943951023931953" />
   </joint>
   <link  name="motor_link_2" >
    <inertial >
     <mass  value="0.01" />
     <inertia  izz="0.001"  ixz="0.0"  iyy="0.001"  ixy="0.0"  iyz="0.0"  ixx="0.001" />
    </inertial>
    <visual >
     <origin  xyz="0 0 0.01"  rpy="0 0 0" />
     <geometry >
      <box  size="0.01 0.002 0.02" />
     </geometry>
     <material  name="BananaYellow" />
    </visual>
    <collision >
     <origin  xyz="0 0 0.01"  rpy="0 0 0" />
     <geometry >
      <box  size="0.01 0.002 0.02" />
     </geometry>
     <material  name="BananaYellow" />
    </collision>
   </link>
   <joint  name="motor_joint_3"  type="prismatic" >
    <axis  xyz="0 0 1" />
    <limit  velocity="1"  upper="0.1"  lower="0.0"  effort="100" />
    <parent  link="dbase_link" />
    <child  link="motor_link_3" />
    <origin  xyz="-0.017320508075688773 -0.06 0.0"  rpy="0 0 2.0943951023931953" />
   </joint>
   <link  name="motor_link_3" >
    <inertial >
     <mass  value="0.01" />
     <inertia  izz="0.001"  ixz="0.0"  iyy="0.001"  ixy="0.0"  iyz="0.0"  ixx="0.001" />
    </inertial>
    <visual >
     <origin  xyz="0 0 0.01"  rpy="0 0 0" />
     <geometry >
      <box  size="0.01 0.002 0.02" />
     </geometry>
     <material  name="BananaYellow" />
    </visual>
    <collision >
     <origin  xyz="0 0 0.01"  rpy="0 0 0" />
     <geometry >
      <box  size="0.01 0.002 0.02" />
     </geometry>
     <material  name="BananaYellow" />
    </collision>
   </link>
   <joint  name="motor_joint_4"  type="prismatic" >
    <axis  xyz="0 0 1" />
    <limit  velocity="1"  upper="0.1"  lower="0.0"  effort="100" />
    <parent  link="dbase_link" />
    <child  link="motor_link_4" />
    <origin  xyz="0.06 0.017320508075688773 0.0"  rpy="0 0 -0.5235987755982988" />
   </joint>
   <link  name="motor_link_4" >
    <inertial >
     <mass  value="0.01" />
     <inertia  izz="0.001"  ixz="0.0"  iyy="0.001"  ixy="0.0"  iyz="0.0"  ixx="0.001" />
    </inertial>
    <visual >
     <origin  xyz="0 0 0.01"  rpy="0 0 0" />
     <geometry >
      <box  size="0.01 0.002 0.02" />
     </geometry>
     <material  name="BananaYellow" />
    </visual>
    <collision >
     <origin  xyz="0 0 0.01"  rpy="0 0 0" />
     <geometry >
      <box  size="0.01 0.002 0.02" />
     </geometry>
     <material  name="BananaYellow" />
    </collision>
   </link>
   <joint  name="motor_joint_5"  type="prismatic" >
    <axis  xyz="0 0 1" />
    <limit  velocity="1"  upper="0.1"  lower="0.0"  effort="100" />
    <parent  link="dbase_link" />
    <child  link="motor_link_5" />
    <origin  xyz="0.06 -0.017320508075688773 0.0"  rpy="0 0 -2.6179938779914944" />
   </joint>
   <link  name="motor_link_5" >
    <inertial >
     <mass  value="0.01" />
     <inertia  izz="0.001"  ixz="0.0"  iyy="0.001"  ixy="0.0"  iyz="0.0"  ixx="0.001" />
    </inertial>
    <visual >
     <origin  xyz="0 0 0.01"  rpy="0 0 0" />
     <geometry >
      <box  size="0.01 0.002 0.02" />
     </geometry>
     <material  name="BananaYellow" />
    </visual>
    <collision >
     <origin  xyz="0 0 0.01"  rpy="0 0 0" />
     <geometry >
      <box  size="0.01 0.002 0.02" />
     </geometry>
     <material  name="BananaYellow" />
    </collision>
   </link>
   <joint  name="motor_joint_6"  type="prismatic" >
    <axis  xyz="0 0 1" />
    <limit  velocity="1"  upper="0.1"  lower="0.0"  effort="100" />
    <parent  link="dbase_link" />
    <child  link="motor_link_6" />
    <origin  xyz="-0.017320508075688773 0.06 0.0"  rpy="0 0 1.0471975511965976" />
   </joint>
   <link  name="motor_link_6" >
    <inertial >
     <mass  value="0.01" />
     <inertia  izz="0.001"  ixz="0.0"  iyy="0.001"  ixy="0.0"  iyz="0.0"  ixx="0.001" />
    </inertial>
    <visual >
     <origin  xyz="0 0 0.01"  rpy="0 0 0" />
     <geometry >
      <box  size="0.01 0.002 0.02" />
     </geometry>
     <material  name="BananaYellow" />
    </visual>
    <collision >
     <origin  xyz="0 0 0.01"  rpy="0 0 0" />
     <geometry >
      <box  size="0.01 0.002 0.02" />
     </geometry>
     <material  name="BananaYellow" />
    </collision>
   </link>
   <joint  name="motor_joint_7"  type="prismatic" >
    <axis  xyz="0 0 1" />
    <limit  velocity="1"  upper="0.1"  lower="0.0"  effort="100" />
    <parent  link="dbase_link" />
    <child  link="motor_link_7" />
    <origin  xyz="0.017320508075688773 0.06 0.0"  rpy="0 0 -1.0471975511965976" />
   </joint>
   <link  name="motor_link_7" >
    <inertial >
     <mass  value="0.01" />
     <inertia  izz="0.001"  ixz="0.0"  iyy="0.001"  ixy="0.0"  iyz="0.0"  ixx="0.001" />
    </inertial>
    <visual >
     <origin  xyz="0 0 0.01"  rpy="0 0 0" />
     <geometry >
      <box  size="0.01 0.002 0.02" />
     </geometry>
     <material  name="BananaYellow" />
    </visual>
    <collision >
     <origin  xyz="0 0 0.01"  rpy="0 0 0" />
     <geometry >
      <box  size="0.01 0.002 0.02" />
     </geometry>
     <material  name="BananaYellow" />
    </collision>
   </link>
   <joint  name="motor_joint_8"  type="prismatic" >
    <axis  xyz="0 0 1" />
    <limit  velocity="1"  upper="0.1"  lower="0.0"  effort="100" />
    <parent  link="dbase_link" />
    <child  link="motor_link_8" />
    <origin  xyz="-0.06 -0.017320508075688773 0.0"  rpy="0 0 2.6179938779914944" />
   </joint>
   <link  name="motor_link_8" >
    <inertial >
     <mass  value="0.01" />
     <inertia  izz="0.001"  ixz="0.0"  iyy="0.001"  ixy="0.0"  iyz="0.0"  ixx="0.001" />
    </inertial>
    <visual >
     <origin  xyz="0 0 0.01"  rpy="0 0 0" />
     <geometry >
      <box  size="0.01 0.002 0.02" />
     </geometry>
     <material  name="BananaYellow" />
    </visual>
    <collision >
     <origin  xyz="0 0 0.01"  rpy="0 0 0" />
     <geometry >
      <box  size="0.01 0.002 0.02" />
     </geometry>
     <material  name="BananaYellow" />
    </collision>
   </link>
   <joint  name="motor_joint_9"  type="prismatic" >
    <axis  xyz="0 0 1" />
    <limit  velocity="1"  upper="0.1"  lower="0.0"  effort="100" />
    <parent  link="dbase_link" />
    <child  link="motor_link_9" />
    <origin  xyz="-0.06 0.017320508075688773 0.0"  rpy="0 0 0.5235987755982988" />
   </joint>
   <link  name="motor_link_9" >
    <inertial >
     <mass  value="0.01" />
     <inertia  izz="0.001"  ixz="0.0"  iyy="0.001"  ixy="0.0"  iyz="0.0"  ixx="0.001" />
    </inertial>
    <visual >
     <origin  xyz="0 0 0.01"  rpy="0 0 0" />
     <geometry >
      <box  size="0.01 0.002 0.02" />
     </geometry>
     <material  name="BananaYellow" />
    </visual>
    <collision >
     <origin  xyz="0 0 0.01"  rpy="0 0 0" />
     <geometry >
      <box  size="0.01 0.002 0.02" />
     </geometry>
     <material  name="BananaYellow" />
    </collision>
   </link>
   <joint  name="bar_joint_1"  type="fixed" >
    <parent  link="motor_link_1" />
    <child  link="bar_link_1" />
    <origin  xyz="0 0 0.02"  rpy="1.5707963267948966 0 0.0" />
   </joint>
   <link  name="bar_link_1" >
    <inertial >
     <mass  value="0.01" />
     <inertia  izz="0.001"  ixz="0.0"  iyy="0.001"  ixy="0.0"  iyz="0.0"  ixx="0.001" />
    </inertial>
    <visual >
     <origin  xyz="0 0 0.015"  rpy="0 0 0" />
     <geometry >
      <cylinder  length="0.03"  radius="0.001" />
     </geometry>
     <material  name="Grey" />
    </visual>
    <collision >
     <origin  xyz="0 0 0.015"  rpy="0 0 0" />
     <geometry >
      <cylinder  length="0.03"  radius="0.001" />
     </geometry>
     <material  name="Grey" />
    </collision>
   </link>
   <joint  name="bar_joint_2"  type="fixed" >
    <parent  link="motor_link_1" />
    <child  link="bar_link_2" />
    <origin  xyz="0 0 0.02"  rpy="1.5707963267948966 0 1.5707963267948966" />
   </joint>
   <link  name="bar_link_2" >
    <inertial >
     <mass  value="0.01" />
     <inertia  izz="0.001"  ixz="0.0"  iyy="0.001"  ixy="0.0"  iyz="0.0"  ixx="0.001" />
    </inertial>
    <visual >
     <origin  xyz="0 0 0.015"  rpy="0 0 0" />
     <geometry >
      <cylinder  length="0.03"  radius="0.001" />
     </geometry>
     <material  name="Grey" />
    </visual>
    <collision >
     <origin  xyz="0 0 0.015"  rpy="0 0 0" />
     <geometry >
      <cylinder  length="0.03"  radius="0.001" />
     </geometry>
     <material  name="Grey" />
    </collision>
   </link>
   <joint  name="bar_joint_3"  type="fixed" >
    <parent  link="motor_link_1" />
    <child  link="bar_link_3" />
    <origin  xyz="0 0 0.02"  rpy="1.5707963267948966 0 3.141592653589793" />
   </joint>
   <link  name="bar_link_3" >
    <inertial >
     <mass  value="0.01" />
     <inertia  izz="0.001"  ixz="0.0"  iyy="0.001"  ixy="0.0"  iyz="0.0"  ixx="0.001" />
    </inertial>
    <visual >
     <origin  xyz="0 0 0.015"  rpy="0 0 0" />
     <geometry >
      <cylinder  length="0.03"  radius="0.001" />
     </geometry>
     <material  name="Grey" />
    </visual>
    <collision >
     <origin  xyz="0 0 0.015"  rpy="0 0 0" />
     <geometry >
      <cylinder  length="0.03"  radius="0.001" />
     </geometry>
     <material  name="Grey" />
    </collision>
   </link>
   <joint  name="bar_joint_4"  type="fixed" >
    <parent  link="motor_link_1" />
    <child  link="bar_link_4" />
    <origin  xyz="0 0 0.02"  rpy="1.5707963267948966 0 -1.5707963267948966" />
   </joint>
   <link  name="bar_link_4" >
    <inertial >
     <mass  value="0.01" />
     <inertia  izz="0.001"  ixz="0.0"  iyy="0.001"  ixy="0.0"  iyz="0.0"  ixx="0.001" />
    </inertial>
    <visual >
     <origin  xyz="0 0 0.015"  rpy="0 0 0" />
     <geometry >
      <cylinder  length="0.03"  radius="0.001" />
     </geometry>
     <material  name="Grey" />
    </visual>
    <collision >
     <origin  xyz="0 0 0.015"  rpy="0 0 0" />
     <geometry >
      <cylinder  length="0.03"  radius="0.001" />
     </geometry>
     <material  name="Grey" />
    </collision>
   </link>
   <joint  name="parallel_1_kneejoint"  type="revolute" >
    <axis  xyz="1 0 0" />
    <limit  velocity="1"  upper="3.141592653589793"  lower="-3.141592653589793"  effort="100" />
    <parent  link="bar_link_1" />
    <child  link="parallel_1_knee" />
    <origin  xyz="0 0 0.03"  rpy="-1.5707963267948966 0 0" />
   </joint>
   <link  name="parallel_1_knee" >
    <inertial >
     <mass  value="0.01" />
     <inertia  izz="0.001"  ixz="0.0"  iyy="0.001"  ixy="0.0"  iyz="0.0"  ixx="0.001" />
    </inertial>
    <visual >
     <origin  xyz="0 0 0"  rpy="0 1.5707963267948966 0" />
     <geometry >
      <cylinder  length="0.015"  radius="0.001" />
     </geometry>
     <material  name="Red" />
    </visual>
    <collision >
     <origin  xyz="0 0 0"  rpy="0 1.5707963267948966 0" />
     <geometry >
      <cylinder  length="0.015"  radius="0.001" />
     </geometry>
     <material  name="Red" />
    </collision>
   </link>
   <joint  name="parallel_1_legjoint1"  type="revolute" >
    <axis  xyz="0 1 0" />
    <limit  velocity="1"  upper="1.5707963267948966"  lower="-1.5707963267948966"  effort="100" />
    <parent  link="parallel_1_knee" />
    <child  link="parallel_1_leg1" />
    <origin  xyz="-0.005 0 0"  rpy="0 0 0" />
   </joint>
   <joint  name="parallel_1_legjoint2"  type="revolute" >
    <axis  xyz="0 1 0" />
    <limit  velocity="1"  upper="1.5707963267948966"  lower="-1.5707963267948966"  effort="100" />
    <parent  link="parallel_1_knee" />
    <child  link="parallel_1_leg2" />
    <origin  xyz="0.005 0 0"  rpy="0 0 0" />
   </joint>
   <link  name="parallel_1_leg1" >
    <inertial >
     <mass  value="0.01" />
     <inertia  izz="0.001"  ixz="0.0"  iyy="0.001"  ixy="0.0"  iyz="0.0"  ixx="0.001" />
    </inertial>
    <visual >
     <origin  xyz="0 0 0.02"  rpy="0 0 0" />
     <geometry >
      <box  size="0.002 0.002 0.04" />
     </geometry>
     <material  name="white" />
    </visual>
    <collision >
     <origin  xyz="0 0 0.02"  rpy="0 0 0" />
     <geometry >
      <box  size="0.002 0.002 0.04" />
     </geometry>
     <material  name="white" />
    </collision>
   </link>
   <link  name="parallel_1_leg2" >
    <inertial >
     <mass  value="0.01" />
     <inertia  izz="0.001"  ixz="0.0"  iyy="0.001"  ixy="0.0"  iyz="0.0"  ixx="0.001" />
    </inertial>
    <visual >
     <origin  xyz="0 0 0.02"  rpy="0 0 0" />
     <geometry >
      <box  size="0.002 0.002 0.04" />
     </geometry>
     <material  name="white" />
    </visual>
    <collision >
     <origin  xyz="0 0 0.02"  rpy="0 0 0" />
     <geometry >
      <box  size="0.002 0.002 0.04" />
     </geometry>
     <material  name="white" />
    </collision>
   </link>
   <joint  name="parallel_2_kneejoint"  type="revolute" >
    <axis  xyz="1 0 0" />
    <limit  velocity="1"  upper="3.141592653589793"  lower="-3.141592653589793"  effort="100" />
    <parent  link="bar_link_2" />
    <child  link="parallel_2_knee" />
    <origin  xyz="0 0 0.03"  rpy="-1.5707963267948966 0 0" />
   </joint>
   <link  name="parallel_2_knee" >
    <inertial >
     <mass  value="0.01" />
     <inertia  izz="0.001"  ixz="0.0"  iyy="0.001"  ixy="0.0"  iyz="0.0"  ixx="0.001" />
    </inertial>
    <visual >
     <origin  xyz="0 0 0"  rpy="0 1.5707963267948966 0" />
     <geometry >
      <cylinder  length="0.015"  radius="0.001" />
     </geometry>
     <material  name="Red" />
    </visual>
    <collision >
     <origin  xyz="0 0 0"  rpy="0 1.5707963267948966 0" />
     <geometry >
      <cylinder  length="0.015"  radius="0.001" />
     </geometry>
     <material  name="Red" />
    </collision>
   </link>
   <joint  name="parallel_2_legjoint1"  type="revolute" >
    <axis  xyz="0 1 0" />
    <limit  velocity="1"  upper="1.5707963267948966"  lower="-1.5707963267948966"  effort="100" />
    <parent  link="parallel_2_knee" />
    <child  link="parallel_2_leg1" />
    <origin  xyz="-0.005 0 0"  rpy="0 0 0" />
   </joint>
   <joint  name="parallel_2_legjoint2"  type="revolute" >
    <axis  xyz="0 1 0" />
    <limit  velocity="1"  upper="1.5707963267948966"  lower="-1.5707963267948966"  effort="100" />
    <parent  link="parallel_2_knee" />
    <child  link="parallel_2_leg2" />
    <origin  xyz="0.005 0 0"  rpy="0 0 0" />
   </joint>
   <link  name="parallel_2_leg1" >
    <inertial >
     <mass  value="0.01" />
     <inertia  izz="0.001"  ixz="0.0"  iyy="0.001"  ixy="0.0"  iyz="0.0"  ixx="0.001" />
    </inertial>
    <visual >
     <origin  xyz="0 0 0.02"  rpy="0 0 0" />
     <geometry >
      <box  size="0.002 0.002 0.04" />
     </geometry>
     <material  name="white" />
    </visual>
    <collision >
     <origin  xyz="0 0 0.02"  rpy="0 0 0" />
     <geometry >
      <box  size="0.002 0.002 0.04" />
     </geometry>
     <material  name="white" />
    </collision>
   </link>
   <link  name="parallel_2_leg2" >
    <inertial >
     <mass  value="0.01" />
     <inertia  izz="0.001"  ixz="0.0"  iyy="0.001"  ixy="0.0"  iyz="0.0"  ixx="0.001" />
    </inertial>
    <visual >
     <origin  xyz="0 0 0.02"  rpy="0 0 0" />
     <geometry >
      <box  size="0.002 0.002 0.04" />
     </geometry>
     <material  name="white" />
    </visual>
    <collision >
     <origin  xyz="0 0 0.02"  rpy="0 0 0" />
     <geometry >
      <box  size="0.002 0.002 0.04" />
     </geometry>
     <material  name="white" />
    </collision>
   </link>
   <joint  name="parallel_3_kneejoint"  type="revolute" >
    <axis  xyz="1 0 0" />
    <limit  velocity="1"  upper="3.141592653589793"  lower="-3.141592653589793"  effort="100" />
    <parent  link="bar_link_3" />
    <child  link="parallel_3_knee" />
    <origin  xyz="0 0 0.03"  rpy="-1.5707963267948966 0 0" />
   </joint>
   <link  name="parallel_3_knee" >
    <inertial >
     <mass  value="0.01" />
     <inertia  izz="0.001"  ixz="0.0"  iyy="0.001"  ixy="0.0"  iyz="0.0"  ixx="0.001" />
    </inertial>
    <visual >
     <origin  xyz="0 0 0"  rpy="0 1.5707963267948966 0" />
     <geometry >
      <cylinder  length="0.015"  radius="0.001" />
     </geometry>
     <material  name="Red" />
    </visual>
    <collision >
     <origin  xyz="0 0 0"  rpy="0 1.5707963267948966 0" />
     <geometry >
      <cylinder  length="0.015"  radius="0.001" />
     </geometry>
     <material  name="Red" />
    </collision>
   </link>
   <joint  name="parallel_3_legjoint1"  type="revolute" >
    <axis  xyz="0 1 0" />
    <limit  velocity="1"  upper="1.5707963267948966"  lower="-1.5707963267948966"  effort="100" />
    <parent  link="parallel_3_knee" />
    <child  link="parallel_3_leg1" />
    <origin  xyz="-0.005 0 0"  rpy="0 0 0" />
   </joint>
   <joint  name="parallel_3_legjoint2"  type="revolute" >
    <axis  xyz="0 1 0" />
    <limit  velocity="1"  upper="1.5707963267948966"  lower="-1.5707963267948966"  effort="100" />
    <parent  link="parallel_3_knee" />
    <child  link="parallel_3_leg2" />
    <origin  xyz="0.005 0 0"  rpy="0 0 0" />
   </joint>
   <link  name="parallel_3_leg1" >
    <inertial >
     <mass  value="0.01" />
     <inertia  izz="0.001"  ixz="0.0"  iyy="0.001"  ixy="0.0"  iyz="0.0"  ixx="0.001" />
    </inertial>
    <visual >
     <origin  xyz="0 0 0.02"  rpy="0 0 0" />
     <geometry >
      <box  size="0.002 0.002 0.04" />
     </geometry>
     <material  name="white" />
    </visual>
    <collision >
     <origin  xyz="0 0 0.02"  rpy="0 0 0" />
     <geometry >
      <box  size="0.002 0.002 0.04" />
     </geometry>
     <material  name="white" />
    </collision>
   </link>
   <link  name="parallel_3_leg2" >
    <inertial >
     <mass  value="0.01" />
     <inertia  izz="0.001"  ixz="0.0"  iyy="0.001"  ixy="0.0"  iyz="0.0"  ixx="0.001" />
    </inertial>
    <visual >
     <origin  xyz="0 0 0.02"  rpy="0 0 0" />
     <geometry >
      <box  size="0.002 0.002 0.04" />
     </geometry>
     <material  name="white" />
    </visual>
    <collision >
     <origin  xyz="0 0 0.02"  rpy="0 0 0" />
     <geometry >
      <box  size="0.002 0.002 0.04" />
     </geometry>
     <material  name="white" />
    </collision>
   </link>
   <joint  name="parallel_4_kneejoint"  type="revolute" >
    <axis  xyz="1 0 0" />
    <limit  velocity="1"  upper="3.141592653589793"  lower="-3.141592653589793"  effort="100" />
    <parent  link="bar_link_4" />
    <child  link="parallel_4_knee" />
    <origin  xyz="0 0 0.03"  rpy="-1.5707963267948966 0 0" />
   </joint>
   <link  name="parallel_4_knee" >
    <inertial >
     <mass  value="0.01" />
     <inertia  izz="0.001"  ixz="0.0"  iyy="0.001"  ixy="0.0"  iyz="0.0"  ixx="0.001" />
    </inertial>
    <visual >
     <origin  xyz="0 0 0"  rpy="0 1.5707963267948966 0" />
     <geometry >
      <cylinder  length="0.015"  radius="0.001" />
     </geometry>
     <material  name="Red" />
    </visual>
    <collision >
     <origin  xyz="0 0 0"  rpy="0 1.5707963267948966 0" />
     <geometry >
      <cylinder  length="0.015"  radius="0.001" />
     </geometry>
     <material  name="Red" />
    </collision>
   </link>
   <joint  name="parallel_4_legjoint1"  type="revolute" >
    <axis  xyz="0 1 0" />
    <limit  velocity="1"  upper="1.5707963267948966"  lower="-1.5707963267948966"  effort="100" />
    <parent  link="parallel_4_knee" />
    <child  link="parallel_4_leg1" />
    <origin  xyz="-0.005 0 0"  rpy="0 0 0" />
   </joint>
   <joint  name="parallel_4_legjoint2"  type="revolute" >
    <axis  xyz="0 1 0" />
    <limit  velocity="1"  upper="1.5707963267948966"  lower="-1.5707963267948966"  effort="100" />
    <parent  link="parallel_4_knee" />
    <child  link="parallel_4_leg2" />
    <origin  xyz="0.005 0 0"  rpy="0 0 0" />
   </joint>
   <link  name="parallel_4_leg1" >
    <inertial >
     <mass  value="0.01" />
     <inertia  izz="0.001"  ixz="0.0"  iyy="0.001"  ixy="0.0"  iyz="0.0"  ixx="0.001" />
    </inertial>
    <visual >
     <origin  xyz="0 0 0.02"  rpy="0 0 0" />
     <geometry >
      <box  size="0.002 0.002 0.04" />
     </geometry>
     <material  name="white" />
    </visual>
    <collision >
     <origin  xyz="0 0 0.02"  rpy="0 0 0" />
     <geometry >
      <box  size="0.002 0.002 0.04" />
     </geometry>
     <material  name="white" />
    </collision>
   </link>
   <link  name="parallel_4_leg2" >
    <inertial >
     <mass  value="0.01" />
     <inertia  izz="0.001"  ixz="0.0"  iyy="0.001"  ixy="0.0"  iyz="0.0"  ixx="0.001" />
    </inertial>
    <visual >
     <origin  xyz="0 0 0.02"  rpy="0 0 0" />
     <geometry >
      <box  size="0.002 0.002 0.04" />
     </geometry>
     <material  name="white" />
    </visual>
    <collision >
     <origin  xyz="0 0 0.02"  rpy="0 0 0" />
     <geometry >
      <box  size="0.002 0.002 0.04" />
     </geometry>
     <material  name="white" />
    </collision>
   </link>
   <joint  name="parallel_5_kneejoint"  type="revolute" >
    <axis  xyz="1 0 0" />
    <limit  velocity="1"  upper="3.141592653589793"  lower="-3.141592653589793"  effort="100" />
    <parent  link="motor_link_2" />
    <child  link="parallel_5_knee" />
    <origin  xyz="0 0 0.02"  rpy="0 0 0" />
   </joint>
   <link  name="parallel_5_knee" >
    <inertial >
     <mass  value="0.01" />
     <inertia  izz="0.001"  ixz="0.0"  iyy="0.001"  ixy="0.0"  iyz="0.0"  ixx="0.001" />
    </inertial>
    <visual >
     <origin  xyz="0 0 0"  rpy="0 1.5707963267948966 0" />
     <geometry >
      <cylinder  length="0.015"  radius="0.001" />
     </geometry>
     <material  name="Red" />
    </visual>
    <collision >
     <origin  xyz="0 0 0"  rpy="0 1.5707963267948966 0" />
     <geometry >
      <cylinder  length="0.015"  radius="0.001" />
     </geometry>
     <material  name="Red" />
    </collision>
   </link>
   <joint  name="parallel_5_legjoint1"  type="revolute" >
    <axis  xyz="0 1 0" />
    <limit  velocity="1"  upper="1.5707963267948966"  lower="-1.5707963267948966"  effort="100" />
    <parent  link="parallel_5_knee" />
    <child  link="parallel_5_leg1" />
    <origin  xyz="-0.005 0 0"  rpy="0 0 0" />
   </joint>
   <joint  name="parallel_5_legjoint2"  type="revolute" >
    <axis  xyz="0 1 0" />
    <limit  velocity="1"  upper="1.5707963267948966"  lower="-1.5707963267948966"  effort="100" />
    <parent  link="parallel_5_knee" />
    <child  link="parallel_5_leg2" />
    <origin  xyz="0.005 0 0"  rpy="0 0 0" />
   </joint>
   <link  name="parallel_5_leg1" >
    <inertial >
     <mass  value="0.01" />
     <inertia  izz="0.001"  ixz="0.0"  iyy="0.001"  ixy="0.0"  iyz="0.0"  ixx="0.001" />
    </inertial>
    <visual >
     <origin  xyz="0 0 0.02"  rpy="0 0 0" />
     <geometry >
      <box  size="0.002 0.002 0.04" />
     </geometry>
     <material  name="white" />
    </visual>
    <collision >
     <origin  xyz="0 0 0.02"  rpy="0 0 0" />
     <geometry >
      <box  size="0.002 0.002 0.04" />
     </geometry>
     <material  name="white" />
    </collision>
   </link>
   <link  name="parallel_5_leg2" >
    <inertial >
     <mass  value="0.01" />
     <inertia  izz="0.001"  ixz="0.0"  iyy="0.001"  ixy="0.0"  iyz="0.0"  ixx="0.001" />
    </inertial>
    <visual >
     <origin  xyz="0 0 0.02"  rpy="0 0 0" />
     <geometry >
      <box  size="0.002 0.002 0.04" />
     </geometry>
     <material  name="white" />
    </visual>
    <collision >
     <origin  xyz="0 0 0.02"  rpy="0 0 0" />
     <geometry >
      <box  size="0.002 0.002 0.04" />
     </geometry>
     <material  name="white" />
    </collision>
   </link>
   <joint  name="parallel_6_kneejoint"  type="revolute" >
    <axis  xyz="1 0 0" />
    <limit  velocity="1"  upper="3.141592653589793"  lower="-3.141592653589793"  effort="100" />
    <parent  link="motor_link_3" />
    <child  link="parallel_6_knee" />
    <origin  xyz="0 0 0.02"  rpy="0 0 0" />
   </joint>
   <link  name="parallel_6_knee" >
    <inertial >
     <mass  value="0.01" />
     <inertia  izz="0.001"  ixz="0.0"  iyy="0.001"  ixy="0.0"  iyz="0.0"  ixx="0.001" />
    </inertial>
    <visual >
     <origin  xyz="0 0 0"  rpy="0 1.5707963267948966 0" />
     <geometry >
      <cylinder  length="0.015"  radius="0.001" />
     </geometry>
     <material  name="Red" />
    </visual>
    <collision >
     <origin  xyz="0 0 0"  rpy="0 1.5707963267948966 0" />
     <geometry >
      <cylinder  length="0.015"  radius="0.001" />
     </geometry>
     <material  name="Red" />
    </collision>
   </link>
   <joint  name="parallel_6_legjoint1"  type="revolute" >
    <axis  xyz="0 1 0" />
    <limit  velocity="1"  upper="1.5707963267948966"  lower="-1.5707963267948966"  effort="100" />
    <parent  link="parallel_6_knee" />
    <child  link="parallel_6_leg1" />
    <origin  xyz="-0.005 0 0"  rpy="0 0 0" />
   </joint>
   <joint  name="parallel_6_legjoint2"  type="revolute" >
    <axis  xyz="0 1 0" />
    <limit  velocity="1"  upper="1.5707963267948966"  lower="-1.5707963267948966"  effort="100" />
    <parent  link="parallel_6_knee" />
    <child  link="parallel_6_leg2" />
    <origin  xyz="0.005 0 0"  rpy="0 0 0" />
   </joint>
   <link  name="parallel_6_leg1" >
    <inertial >
     <mass  value="0.01" />
     <inertia  izz="0.001"  ixz="0.0"  iyy="0.001"  ixy="0.0"  iyz="0.0"  ixx="0.001" />
    </inertial>
    <visual >
     <origin  xyz="0 0 0.02"  rpy="0 0 0" />
     <geometry >
      <box  size="0.002 0.002 0.04" />
     </geometry>
     <material  name="white" />
    </visual>
    <collision >
     <origin  xyz="0 0 0.02"  rpy="0 0 0" />
     <geometry >
      <box  size="0.002 0.002 0.04" />
     </geometry>
     <material  name="white" />
    </collision>
   </link>
   <link  name="parallel_6_leg2" >
    <inertial >
     <mass  value="0.01" />
     <inertia  izz="0.001"  ixz="0.0"  iyy="0.001"  ixy="0.0"  iyz="0.0"  ixx="0.001" />
    </inertial>
    <visual >
     <origin  xyz="0 0 0.02"  rpy="0 0 0" />
     <geometry >
      <box  size="0.002 0.002 0.04" />
     </geometry>
     <material  name="white" />
    </visual>
    <collision >
     <origin  xyz="0 0 0.02"  rpy="0 0 0" />
     <geometry >
      <box  size="0.002 0.002 0.04" />
     </geometry>
     <material  name="white" />
    </collision>
   </link>
   <joint  name="parallel_7_kneejoint"  type="revolute" >
    <axis  xyz="1 0 0" />
    <limit  velocity="1"  upper="3.141592653589793"  lower="-3.141592653589793"  effort="100" />
    <parent  link="motor_link_4" />
    <child  link="parallel_7_knee" />
    <origin  xyz="0 0 0.02"  rpy="0 0 0" />
   </joint>
   <link  name="parallel_7_knee" >
    <inertial >
     <mass  value="0.01" />
     <inertia  izz="0.001"  ixz="0.0"  iyy="0.001"  ixy="0.0"  iyz="0.0"  ixx="0.001" />
    </inertial>
    <visual >
     <origin  xyz="0 0 0"  rpy="0 1.5707963267948966 0" />
     <geometry >
      <cylinder  length="0.015"  radius="0.001" />
     </geometry>
     <material  name="Red" />
    </visual>
    <collision >
     <origin  xyz="0 0 0"  rpy="0 1.5707963267948966 0" />
     <geometry >
      <cylinder  length="0.015"  radius="0.001" />
     </geometry>
     <material  name="Red" />
    </collision>
   </link>
   <joint  name="parallel_7_legjoint1"  type="revolute" >
    <axis  xyz="0 1 0" />
    <limit  velocity="1"  upper="1.5707963267948966"  lower="-1.5707963267948966"  effort="100" />
    <parent  link="parallel_7_knee" />
    <child  link="parallel_7_leg1" />
    <origin  xyz="-0.005 0 0"  rpy="0 0 0" />
   </joint>
   <joint  name="parallel_7_legjoint2"  type="revolute" >
    <axis  xyz="0 1 0" />
    <limit  velocity="1"  upper="1.5707963267948966"  lower="-1.5707963267948966"  effort="100" />
    <parent  link="parallel_7_knee" />
    <child  link="parallel_7_leg2" />
    <origin  xyz="0.005 0 0"  rpy="0 0 0" />
   </joint>
   <link  name="parallel_7_leg1" >
    <inertial >
     <mass  value="0.01" />
     <inertia  izz="0.001"  ixz="0.0"  iyy="0.001"  ixy="0.0"  iyz="0.0"  ixx="0.001" />
    </inertial>
    <visual >
     <origin  xyz="0 0 0.02"  rpy="0 0 0" />
     <geometry >
      <box  size="0.002 0.002 0.04" />
     </geometry>
     <material  name="white" />
    </visual>
    <collision >
     <origin  xyz="0 0 0.02"  rpy="0 0 0" />
     <geometry >
      <box  size="0.002 0.002 0.04" />
     </geometry>
     <material  name="white" />
    </collision>
   </link>
   <link  name="parallel_7_leg2" >
    <inertial >
     <mass  value="0.01" />
     <inertia  izz="0.001"  ixz="0.0"  iyy="0.001"  ixy="0.0"  iyz="0.0"  ixx="0.001" />
    </inertial>
    <visual >
     <origin  xyz="0 0 0.02"  rpy="0 0 0" />
     <geometry >
      <box  size="0.002 0.002 0.04" />
     </geometry>
     <material  name="white" />
    </visual>
    <collision >
     <origin  xyz="0 0 0.02"  rpy="0 0 0" />
     <geometry >
      <box  size="0.002 0.002 0.04" />
     </geometry>
     <material  name="white" />
    </collision>
   </link>
   <joint  name="parallel_8_kneejoint"  type="revolute" >
    <axis  xyz="1 0 0" />
    <limit  velocity="1"  upper="3.141592653589793"  lower="-3.141592653589793"  effort="100" />
    <parent  link="motor_link_5" />
    <child  link="parallel_8_knee" />
    <origin  xyz="0 0 0.02"  rpy="0 0 0" />
   </joint>
   <link  name="parallel_8_knee" >
    <inertial >
     <mass  value="0.01" />
     <inertia  izz="0.001"  ixz="0.0"  iyy="0.001"  ixy="0.0"  iyz="0.0"  ixx="0.001" />
    </inertial>
    <visual >
     <origin  xyz="0 0 0"  rpy="0 1.5707963267948966 0" />
     <geometry >
      <cylinder  length="0.015"  radius="0.001" />
     </geometry>
     <material  name="Red" />
    </visual>
    <collision >
     <origin  xyz="0 0 0"  rpy="0 1.5707963267948966 0" />
     <geometry >
      <cylinder  length="0.015"  radius="0.001" />
     </geometry>
     <material  name="Red" />
    </collision>
   </link>
   <joint  name="parallel_8_legjoint1"  type="revolute" >
    <axis  xyz="0 1 0" />
    <limit  velocity="1"  upper="1.5707963267948966"  lower="-1.5707963267948966"  effort="100" />
    <parent  link="parallel_8_knee" />
    <child  link="parallel_8_leg1" />
    <origin  xyz="-0.005 0 0"  rpy="0 0 0" />
   </joint>
   <joint  name="parallel_8_legjoint2"  type="revolute" >
    <axis  xyz="0 1 0" />
    <limit  velocity="1"  upper="1.5707963267948966"  lower="-1.5707963267948966"  effort="100" />
    <parent  link="parallel_8_knee" />
    <child  link="parallel_8_leg2" />
    <origin  xyz="0.005 0 0"  rpy="0 0 0" />
   </joint>
   <link  name="parallel_8_leg1" >
    <inertial >
     <mass  value="0.01" />
     <inertia  izz="0.001"  ixz="0.0"  iyy="0.001"  ixy="0.0"  iyz="0.0"  ixx="0.001" />
    </inertial>
    <visual >
     <origin  xyz="0 0 0.02"  rpy="0 0 0" />
     <geometry >
      <box  size="0.002 0.002 0.04" />
     </geometry>
     <material  name="white" />
    </visual>
    <collision >
     <origin  xyz="0 0 0.02"  rpy="0 0 0" />
     <geometry >
      <box  size="0.002 0.002 0.04" />
     </geometry>
     <material  name="white" />
    </collision>
   </link>
   <link  name="parallel_8_leg2" >
    <inertial >
     <mass  value="0.01" />
     <inertia  izz="0.001"  ixz="0.0"  iyy="0.001"  ixy="0.0"  iyz="0.0"  ixx="0.001" />
    </inertial>
    <visual >
     <origin  xyz="0 0 0.02"  rpy="0 0 0" />
     <geometry >
      <box  size="0.002 0.002 0.04" />
     </geometry>
     <material  name="white" />
    </visual>
    <collision >
     <origin  xyz="0 0 0.02"  rpy="0 0 0" />
     <geometry >
      <box  size="0.002 0.002 0.04" />
     </geometry>
     <material  name="white" />
    </collision>
   </link>
   <joint  name="parallel_9_kneejoint"  type="revolute" >
    <axis  xyz="1 0 0" />
    <limit  velocity="1"  upper="3.141592653589793"  lower="-3.141592653589793"  effort="100" />
    <parent  link="motor_link_6" />
    <child  link="parallel_9_knee" />
    <origin  xyz="0 0 0.02"  rpy="0 0 0" />
   </joint>
   <link  name="parallel_9_knee" >
    <inertial >
     <mass  value="0.01" />
     <inertia  izz="0.001"  ixz="0.0"  iyy="0.001"  ixy="0.0"  iyz="0.0"  ixx="0.001" />
    </inertial>
    <visual >
     <origin  xyz="0 0 0"  rpy="0 1.5707963267948966 0" />
     <geometry >
      <cylinder  length="0.015"  radius="0.001" />
     </geometry>
     <material  name="Red" />
    </visual>
    <collision >
     <origin  xyz="0 0 0"  rpy="0 1.5707963267948966 0" />
     <geometry >
      <cylinder  length="0.015"  radius="0.001" />
     </geometry>
     <material  name="Red" />
    </collision>
   </link>
   <joint  name="parallel_9_legjoint1"  type="revolute" >
    <axis  xyz="0 1 0" />
    <limit  velocity="1"  upper="1.5707963267948966"  lower="-1.5707963267948966"  effort="100" />
    <parent  link="parallel_9_knee" />
    <child  link="parallel_9_leg1" />
    <origin  xyz="-0.005 0 0"  rpy="0 0 0" />
   </joint>
   <joint  name="parallel_9_legjoint2"  type="revolute" >
    <axis  xyz="0 1 0" />
    <limit  velocity="1"  upper="1.5707963267948966"  lower="-1.5707963267948966"  effort="100" />
    <parent  link="parallel_9_knee" />
    <child  link="parallel_9_leg2" />
    <origin  xyz="0.005 0 0"  rpy="0 0 0" />
   </joint>
   <link  name="parallel_9_leg1" >
    <inertial >
     <mass  value="0.01" />
     <inertia  izz="0.001"  ixz="0.0"  iyy="0.001"  ixy="0.0"  iyz="0.0"  ixx="0.001" />
    </inertial>
    <visual >
     <origin  xyz="0 0 0.02"  rpy="0 0 0" />
     <geometry >
      <box  size="0.002 0.002 0.04" />
     </geometry>
     <material  name="white" />
    </visual>
    <collision >
     <origin  xyz="0 0 0.02"  rpy="0 0 0" />
     <geometry >
      <box  size="0.002 0.002 0.04" />
     </geometry>
     <material  name="white" />
    </collision>
   </link>
   <link  name="parallel_9_leg2" >
    <inertial >
     <mass  value="0.01" />
     <inertia  izz="0.001"  ixz="0.0"  iyy="0.001"  ixy="0.0"  iyz="0.0"  ixx="0.001" />
    </inertial>
    <visual >
     <origin  xyz="0 0 0.02"  rpy="0 0 0" />
     <geometry >
      <box  size="0.002 0.002 0.04" />
     </geometry>
     <material  name="white" />
    </visual>
    <collision >
     <origin  xyz="0 0 0.02"  rpy="0 0 0" />
     <geometry >
      <box  size="0.002 0.002 0.04" />
     </geometry>
     <material  name="white" />
    </collision>
   </link>
   <joint  name="parallel_10_kneejoint"  type="revolute" >
    <axis  xyz="1 0 0" />
    <limit  velocity="1"  upper="3.141592653589793"  lower="-3.141592653589793"  effort="100" />
    <parent  link="motor_link_7" />
    <child  link="parallel_10_knee" />
    <origin  xyz="0 0 0.02"  rpy="0 0 0" />
   </joint>
   <link  name="parallel_10_knee" >
    <inertial >
     <mass  value="0.01" />
     <inertia  izz="0.001"  ixz="0.0"  iyy="0.001"  ixy="0.0"  iyz="0.0"  ixx="0.001" />
    </inertial>
    <visual >
     <origin  xyz="0 0 0"  rpy="0 1.5707963267948966 0" />
     <geometry >
      <cylinder  length="0.015"  radius="0.001" />
     </geometry>
     <material  name="Red" />
    </visual>
    <collision >
     <origin  xyz="0 0 0"  rpy="0 1.5707963267948966 0" />
     <geometry >
      <cylinder  length="0.015"  radius="0.001" />
     </geometry>
     <material  name="Red" />
    </collision>
   </link>
   <joint  name="parallel_10_legjoint1"  type="revolute" >
    <axis  xyz="0 1 0" />
    <limit  velocity="1"  upper="1.5707963267948966"  lower="-1.5707963267948966"  effort="100" />
    <parent  link="parallel_10_knee" />
    <child  link="parallel_10_leg1" />
    <origin  xyz="-0.005 0 0"  rpy="0 0 0" />
   </joint>
   <joint  name="parallel_10_legjoint2"  type="revolute" >
    <axis  xyz="0 1 0" />
    <limit  velocity="1"  upper="1.5707963267948966"  lower="-1.5707963267948966"  effort="100" />
    <parent  link="parallel_10_knee" />
    <child  link="parallel_10_leg2" />
    <origin  xyz="0.005 0 0"  rpy="0 0 0" />
   </joint>
   <link  name="parallel_10_leg1" >
    <inertial >
     <mass  value="0.01" />
     <inertia  izz="0.001"  ixz="0.0"  iyy="0.001"  ixy="0.0"  iyz="0.0"  ixx="0.001" />
    </inertial>
    <visual >
     <origin  xyz="0 0 0.02"  rpy="0 0 0" />
     <geometry >
      <box  size="0.002 0.002 0.04" />
     </geometry>
     <material  name="white" />
    </visual>
    <collision >
     <origin  xyz="0 0 0.02"  rpy="0 0 0" />
     <geometry >
      <box  size="0.002 0.002 0.04" />
     </geometry>
     <material  name="white" />
    </collision>
   </link>
   <link  name="parallel_10_leg2" >
    <inertial >
     <mass  value="0.01" />
     <inertia  izz="0.001"  ixz="0.0"  iyy="0.001"  ixy="0.0"  iyz="0.0"  ixx="0.001" />
    </inertial>
    <visual >
     <origin  xyz="0 0 0.02"  rpy="0 0 0" />
     <geometry >
      <box  size="0.002 0.002 0.04" />
     </geometry>
     <material  name="white" />
    </visual>
    <collision >
     <origin  xyz="0 0 0.02"  rpy="0 0 0" />
     <geometry >
      <box  size="0.002 0.002 0.04" />
     </geometry>
     <material  name="white" />
    </collision>
   </link>
   <joint  name="parallel_11_kneejoint"  type="revolute" >
    <axis  xyz="1 0 0" />
    <limit  velocity="1"  upper="3.141592653589793"  lower="-3.141592653589793"  effort="100" />
    <parent  link="motor_link_8" />
    <child  link="parallel_11_knee" />
    <origin  xyz="0 0 0.02"  rpy="0 0 0" />
   </joint>
   <link  name="parallel_11_knee" >
    <inertial >
     <mass  value="0.01" />
     <inertia  izz="0.001"  ixz="0.0"  iyy="0.001"  ixy="0.0"  iyz="0.0"  ixx="0.001" />
    </inertial>
    <visual >
     <origin  xyz="0 0 0"  rpy="0 1.5707963267948966 0" />
     <geometry >
      <cylinder  length="0.015"  radius="0.001" />
     </geometry>
     <material  name="Red" />
    </visual>
    <collision >
     <origin  xyz="0 0 0"  rpy="0 1.5707963267948966 0" />
     <geometry >
      <cylinder  length="0.015"  radius="0.001" />
     </geometry>
     <material  name="Red" />
    </collision>
   </link>
   <joint  name="parallel_11_legjoint1"  type="revolute" >
    <axis  xyz="0 1 0" />
    <limit  velocity="1"  upper="1.5707963267948966"  lower="-1.5707963267948966"  effort="100" />
    <parent  link="parallel_11_knee" />
    <child  link="parallel_11_leg1" />
    <origin  xyz="-0.005 0 0"  rpy="0 0 0" />
   </joint>
   <joint  name="parallel_11_legjoint2"  type="revolute" >
    <axis  xyz="0 1 0" />
    <limit  velocity="1"  upper="1.5707963267948966"  lower="-1.5707963267948966"  effort="100" />
    <parent  link="parallel_11_knee" />
    <child  link="parallel_11_leg2" />
    <origin  xyz="0.005 0 0"  rpy="0 0 0" />
   </joint>
   <link  name="parallel_11_leg1" >
    <inertial >
     <mass  value="0.01" />
     <inertia  izz="0.001"  ixz="0.0"  iyy="0.001"  ixy="0.0"  iyz="0.0"  ixx="0.001" />
    </inertial>
    <visual >
     <origin  xyz="0 0 0.02"  rpy="0 0 0" />
     <geometry >
      <box  size="0.002 0.002 0.04" />
     </geometry>
     <material  name="white" />
    </visual>
    <collision >
     <origin  xyz="0 0 0.02"  rpy="0 0 0" />
     <geometry >
      <box  size="0.002 0.002 0.04" />
     </geometry>
     <material  name="white" />
    </collision>
   </link>
   <link  name="parallel_11_leg2" >
    <inertial >
     <mass  value="0.01" />
     <inertia  izz="0.001"  ixz="0.0"  iyy="0.001"  ixy="0.0"  iyz="0.0"  ixx="0.001" />
    </inertial>
    <visual >
     <origin  xyz="0 0 0.02"  rpy="0 0 0" />
     <geometry >
      <box  size="0.002 0.002 0.04" />
     </geometry>
     <material  name="white" />
    </visual>
    <collision >
     <origin  xyz="0 0 0.02"  rpy="0 0 0" />
     <geometry >
      <box  size="0.002 0.002 0.04" />
     </geometry>
     <material  name="white" />
    </collision>
   </link>
   <joint  name="parallel_12_kneejoint"  type="revolute" >
    <axis  xyz="1 0 0" />
    <limit  velocity="1"  upper="3.141592653589793"  lower="-3.141592653589793"  effort="100" />
    <parent  link="motor_link_9" />
    <child  link="parallel_12_knee" />
    <origin  xyz="0 0 0.02"  rpy="0 0 0" />
   </joint>
   <link  name="parallel_12_knee" >
    <inertial >
     <mass  value="0.01" />
     <inertia  izz="0.001"  ixz="0.0"  iyy="0.001"  ixy="0.0"  iyz="0.0"  ixx="0.001" />
    </inertial>
    <visual >
     <origin  xyz="0 0 0"  rpy="0 1.5707963267948966 0" />
     <geometry >
      <cylinder  length="0.015"  radius="0.001" />
     </geometry>
     <material  name="Red" />
    </visual>
    <collision >
     <origin  xyz="0 0 0"  rpy="0 1.5707963267948966 0" />
     <geometry >
      <cylinder  length="0.015"  radius="0.001" />
     </geometry>
     <material  name="Red" />
    </collision>
   </link>
   <joint  name="parallel_12_legjoint1"  type="revolute" >
    <axis  xyz="0 1 0" />
    <limit  velocity="1"  upper="1.5707963267948966"  lower="-1.5707963267948966"  effort="100" />
    <parent  link="parallel_12_knee" />
    <child  link="parallel_12_leg1" />
    <origin  xyz="-0.005 0 0"  rpy="0 0 0" />
   </joint>
   <joint  name="parallel_12_legjoint2"  type="revolute" >
    <axis  xyz="0 1 0" />
    <limit  velocity="1"  upper="1.5707963267948966"  lower="-1.5707963267948966"  effort="100" />
    <parent  link="parallel_12_knee" />
    <child  link="parallel_12_leg2" />
    <origin  xyz="0.005 0 0"  rpy="0 0 0" />
   </joint>
   <link  name="parallel_12_leg1" >
    <inertial >
     <mass  value="0.01" />
     <inertia  izz="0.001"  ixz="0.0"  iyy="0.001"  ixy="0.0"  iyz="0.0"  ixx="0.001" />
    </inertial>
    <visual >
     <origin  xyz="0 0 0.02"  rpy="0 0 0" />
     <geometry >
      <box  size="0.002 0.002 0.04" />
     </geometry>
     <material  name="white" />
    </visual>
    <collision >
     <origin  xyz="0 0 0.02"  rpy="0 0 0" />
     <geometry >
      <box  size="0.002 0.002 0.04" />
     </geometry>
     <material  name="white" />
    </collision>
   </link>
   <link  name="parallel_12_leg2" >
    <inertial >
     <mass  value="0.01" />
     <inertia  izz="0.001"  ixz="0.0"  iyy="0.001"  ixy="0.0"  iyz="0.0"  ixx="0.001" />
    </inertial>
    <visual >
     <origin  xyz="0 0 0.02"  rpy="0 0 0" />
     <geometry >
      <box  size="0.002 0.002 0.04" />
     </geometry>
     <material  name="white" />
    </visual>
    <collision >
     <origin  xyz="0 0 0.02"  rpy="0 0 0" />
     <geometry >
      <box  size="0.002 0.002 0.04" />
     </geometry>
     <material  name="white" />
    </collision>
   </link>

</robot>
